Workbook
Name Adj_closing_price: OFFSET(#REF!,1,0,COUNT(#REF!),1)
Name cmdOK2_click: [1]!cmdOK2_click
Name Date: OFFSET(#REF!,1,0,COUNT(#REF!),1)
Name PAGE1: [2]GROMM!#REF!
Name PAGE2: #REF!
Name PE_band_1: OFFSET(#REF!,1,0,COUNT(#REF!),1)
Name PE_band_2: OFFSET(#REF!,1,0,COUNT(#REF!),1)
Name PE_band_3: OFFSET(#REF!,1,0,COUNT(#REF!),1)
Name PE_band_4: OFFSET(#REF!,1,0,COUNT(#REF!),1)
Name PE_band_5: OFFSET(#REF!,1,0,COUNT(#REF!),1)
Name Price: [1]Template!#REF!
Name Print_Area_MI: #REF!
Name startCompany: [1]Sheet1!#REF!
Name Units: #REF!

Sheet Valuation
A5: Cost of Equity (Ke) | B5: =B7+(B6*(B8-B7)) -> 0.09
A6: Beta | B6: 1 | C6: https://valueinvesting.io/WISE.L/valuation/wacc
A7: 10 Yr UK Long term government bond yield (Rf) | B7: 0.045 | C7: https://www.bloomberg.com/markets/rates-bonds/government-bonds/uk | J7: Marked yellow can be adjusted to see the change in MIOC and IRR.
A8: Equity Market Risk Premium (Rm) | B8: 0.09 | C8: https://valueinvesting.io/WISE.L/valuation/wacc
A10: Cost of Debt (Kd) | B10: =AVERAGE(Assumptions!B81:G81) -> 0.049415232
A11: Tax Rate | B11: 0.25
A13: Equity | B13: =+'3 Statement Model'!R47 -> 979.9
A14: Debt | B14: =+'3 Statement Model'!R27+'3 Statement Model'!R35 -> 224.2
A15: Cash | B15: =+'3 Statement Model'!R20 -> 10479.2
A17: WACC | B17: =SUM(B13/SUM(B13+B14))*B5+SUM(B14/SUM(B13+B14))*B10*(1-B11) -> 0.080142987
A18: Growth Rate | B18: 0.01
A20: Enterprise Value | B20: =SUM(C44:G45) -> 21017.042
A21: Equity Value | B21: =+B20+SUM(B15-B14) -> 31272.042
A23: Shares Outstanding | B23: =1025000250/1000 -> 1025000.2
C24: MIOC and IRR
A25: Exit Price | B25: =+B21/(B23/1000) -> 30.509302 | C25: The projected MOIC of 2.86x and IRR of 23% are directly derived from DCF model, which forecasts strong grwoth in FCFE over five years. The exit
A26: Entry Price (Dec 2024) | B26: 10.66 | C26: price of 30.51 per share is consistent with the terminal equity valur implied by discounting future FCFE using WACC of 8.01% and terminal growth
A27: MOIC | B27: =+B25/B26 -> 2.8620358 | C27: rate of 1%. These return metrics reflect Wise's ability to scale earnings as volumes grow and operating leverage improve. Importantly, Wise
A28: IRR | B28: =IRR(B50:G50) -> 0.23405641 | C28: serves less than 1% of an estimated £11trillon cross-border transfer market. This vast, under-penetrated market provide a long runway for
C29: customer acquistion, volume expansion, and monetisation.
A30: FCFE - Free cash flow to Equity | C30: BASE | D30: Can be changed to see the change in revenue.
A32: Description | B32: =+'3 Statement Model'!J6 -> 45292 | C32: =+'3 Statement Model'!K6 -> 45658 | D32: =+'3 Statement Model'!L6 -> 46023 | E32: =+'3 Statement Model'!M6 -> 46388 | F32: =+'3 Statement Model'!N6 -> 46753 | G32: =+'3 Statement Model'!O6 -> 47119
A33: Year | B33: 0 | C33: 1 | D33: 2 | E33: 3 | F33: 4 | G33: 5
A35: Net Cash generated from operating activities | B35: =+'3 Statement Model'!J27-'3 Statement Model'!J26 -> 460.2 | C35: =+'3 Statement Model'!K27-+'3 Statement Model'!K26 -> 857.2307 | D35: =+'3 Statement Model'!L27-+'3 Statement Model'!L26 -> 1028.3591 | E35: =+'3 Statement Model'!M27-+'3 Statement Model'!M26 -> 1332.3362 | F35: =+'3 Statement Model'!N27-+'3 Statement Model'!N26 -> 1860.9224 | G35: =+'3 Statement Model'!O27-+'3 Statement Model'!O26 -> 1871.3211
A36: Less:
A37: Capex | B37: =-Assumptions!B34-Assumptions!B52-Assumptions!B53 -> -27.7 | C37: =-Assumptions!C34-Assumptions!C52-Assumptions!C53 -> -18.601777 | D37: =-Assumptions!D34-Assumptions!D52-Assumptions!D53 -> -28.779088 | E37: =-Assumptions!E34-Assumptions!E52-Assumptions!E53 -> -28.203315 | F37: =-Assumptions!F34-Assumptions!F52-Assumptions!F53 -> -34.236325 | G37: =-Assumptions!G34-Assumptions!G52-Assumptions!G53 -> -38.497349
A38: Add:
A39: Net Borrowings | B39: =+'3 Statement Model'!J40 -> -50 | C39: =+'3 Statement Model'!K40 -> -43.511874 | D39: =+'3 Statement Model'!L40 -> 44.045207 | E39: =+'3 Statement Model'!M40 -> -13.222222 | F39: =+'3 Statement Model'!N40 -> -4.2296296 | G39: =+'3 Statement Model'!O40 -> 7.2271605
S40: 7.9b customer deposits
A41: FCFE | B41: =+B35+B37+B39 -> 382.5 | C41: =+C35+C37+C39 -> 795.11705 | D41: =+D35+D37+D39 -> 1043.6252 | E41: =+E35+E37+E39 -> 1290.9106 | F41: =+F35+F37+F39 -> 1822.4565 | G41: =+G35+G37+G39 -> 1840.051
A42: Terminal Value | G42: =SUM(G41)*(1+B18)/B17-B18 -> 23189.186
A43: Discount Factor | C43: =1/(1+$B$17)^C33 -> 0.92580335 | D43: =1/(1+$B$17)^D33 -> 0.85711185 | E43: =1/(1+$B$17)^E33 -> 0.79351702 | F43: =1/(1+$B$17)^F33 -> 0.73464072 | G43: =1/(1+$B$17)^G33 -> 0.68013284
A44: DCF | C44: =+C41*C43 -> 736.12203 | D44: =+D41*D43 -> 894.50353 | E44: =+E41*E43 -> 1024.3595 | F44: =+F41*F43 -> 1338.8508 | G44: =+G41*G43 -> 1251.4791
A45: Terminal Value Disconted | G45: =+G42*G43 -> 15771.727
A50: IRR | B50: =-B26 -> -10.66 | C50: 0 | D50: 0 | E50: 0 | F50: 0 | G50: =+B25 -> 30.509302

Sheet 3 Statement Model
Y1: =SUM(S13)+SUM(S16:S19)+R20-S49 -> -4893.5342 | Z1: =SUM(T13)+SUM(T16:T19)+S20-T49 -> -6704.7287 | AA1: =SUM(U13)+SUM(U16:U19)+T20-U49 -> -9064.1558 | AB1: =SUM(V13)+SUM(V16:V19)+U20-V49 -> -12358.166 | AC1: =SUM(W13)+SUM(W16:W19)+V20-W49 -> -16818.867
A3: INCOME STATEMENT | I3: CASH FLOW STATEMENT | Q3: BALANCE SHEET
A6: All figures are in £m | B6: =+Assumptions!B6 -> 45292 | C6: =+Assumptions!C6 -> 45658 | D6: =+Assumptions!D6 -> 46023 | E6: =+Assumptions!E6 -> 46388 | F6: =+Assumptions!F6 -> 46753 | G6: =+Assumptions!G6 -> 47119 | I6: All figures are in £m | J6: =+B6 -> 45292 | K6: =+C6 -> 45658 | L6: =+D6 -> 46023 | M6: =+E6 -> 46388 | N6: =+F6 -> 46753 | O6: =+G6 -> 47119 | Q6: All figures are in £m | R6: =+J6 -> 45292 | S6: =+K6 -> 45658 | T6: =+L6 -> 46023 | U6: =+M6 -> 46388 | V6: =+N6 -> 46753 | W6: =+O6 -> 47119
A8: Revenue | B8: 1052 | C8: =IF(Valuation!$C$30="BASE",INDEX(Assumptions!$X$33:$X$37,COLUMN(A1)),IF(Valuation!$C$30="Best",INDEX(Assumptions!$W$33:$W$37,COLUMN(A1)),IF(Valuation!$C$30="Worst",INDEX(Assumptions!$V$33:$V$37,COLUMN(A1)),""))) -> 1236.1 | D8: =IF(Valuation!$C$30="BASE",INDEX(Assumptions!$X$33:$X$37,COLUMN(B1)),IF(Valuation!$C$30="Best",INDEX(Assumptions!$W$33:$W$37,COLUMN(B1)),IF(Valuation!$C$30="Worst",INDEX(Assumptions!$V$33:$V$37,COLUMN(B1)),""))) -> 1453.075 | E8: =IF(Valuation!$C$30="BASE",INDEX(Assumptions!$X$33:$X$37,COLUMN(C1)),IF(Valuation!$C$30="Best",INDEX(Assumptions!$W$33:$W$37,COLUMN(C1)),IF(Valuation!$C$30="Worst",INDEX(Assumptions!$V$33:$V$37,COLUMN(C1)),""))) -> 1708.9082 | F8: =IF(Valuation!$C$30="BASE",INDEX(Assumptions!$X$33:$X$37,COLUMN(D1)),IF(Valuation!$C$30="Best",INDEX(Assumptions!$W$33:$W$37,COLUMN(D1)),IF(Valuation!$C$30="Worst",INDEX(Assumptions!$V$33:$V$37,COLUMN(D1)),""))) -> 2010.6909 | G8: =IF(Valuation!$C$30="BASE",INDEX(Assumptions!$X$33:$X$37,COLUMN(E1)),IF(Valuation!$C$30="Best",INDEX(Assumptions!$W$33:$W$37,COLUMN(E1)),IF(Valuation!$C$30="Worst",INDEX(Assumptions!$V$33:$V$37,COLUMN(E1)),""))) -> 2366.8302 | I8: Cash Flows From Operating Activities: | Q8: Non-current Assets
A9: Interest income on customer balances | B9: 485.2 | C9: =+S31*3% -> 569.09066 | D9: =+T31*3% -> 778.18109 | E9: =+U31*3% -> 1064.0937 | F9: =+V31*3% -> 1455.054 | G9: =+W31*3% -> 1989.6574 | I9: Profit For The Year | J9: =+B30 -> 354.6 | K9: =+C30 -> 519.6509 | L9: =+D30 -> 573.72323 | M9: =+E30 -> 649.89907 | N9: =+F30 -> 741.21328 | O9: =+G30 -> 843.19839 | Q9: Deferred Tax Asset | R9: 103 | S9: 103 | T9: 103 | U9: 103 | V9: 103 | W9: 103
A10: Interest expense on customer balances | B10: 0 | I10: Adjustments for: | Q10: Property, Plant and Equipment | R10: 34.3 | S10: =+Assumptions!C48 -> 31.141414 | T10: =+Assumptions!D48 -> 33.615134 | U10: =+Assumptions!E48 -> 29.691642 | V10: =+Assumptions!F48 -> 25.385698 | W10: =+Assumptions!G48 -> 17.689922
A11: Benefits paid relating to customer balances | B11: -124.9 | C11: =(-SUM(C$8:C$9)*0.2)*SUM($B11)/SUM($B$11:$B$13) -> -101.37964 | D11: =(-SUM(D$8:D$9)*0.25)*SUM($B11)/SUM($B$11:$B$13) -> -156.63438 | E11: =(-SUM(E$8:E$9)*0.3)*SUM($B11)/SUM($B$11:$B$13) -> -233.59799 | F11: =(-SUM(F$8:F$9)*0.35)*SUM($B11)/SUM($B$11:$B$13) -> -340.61384 | G11: =(-SUM(G$8:G$9)*0.4)*SUM($B11)/SUM($B$11:$B$13) -> -489.32132 | I11: Depreciation & Amortisation | J11: 18.3 | K11: =-C20 -> 20.937129 | L11: =-D20 -> 25.087621 | M11: =-E20 -> 29.769281 | N11: =-F20 -> 34.508813 | O11: =-G20 -> 39.599916 | Q11: Intangible assets | R11: 6.5 | S11: =+Assumptions!C63 -> 6.2232331 | T11: =+Assumptions!D63 -> 6.3409804 | U11: =+Assumptions!E63 -> 7.5985055 | V11: =+Assumptions!F63 -> 10.531961 | W11: =+Assumptions!G63 -> 16.025171
A12: Cost of sales | B12: -307.4 | C12: =(-SUM(C$8:C$9)*0.2)*SUM($B12)/SUM($B$11:$B$13) -> -249.51241 | D12: =(-SUM(D$8:D$9)*0.25)*SUM($B12)/SUM($B$11:$B$13) -> -385.50367 | E12: =(-SUM(E$8:E$9)*0.3)*SUM($B12)/SUM($B$11:$B$13) -> -574.92411 | F12: =(-SUM(F$8:F$9)*0.35)*SUM($B12)/SUM($B$11:$B$13) -> -838.3082 | G12: =(-SUM(G$8:G$9)*0.4)*SUM($B12)/SUM($B$11:$B$13) -> -1204.3024 | I12: Non cash share based payments expenses | J12: 72.5 | K12: =SUM(J12)/SUM(B19:B20)*C19 -> 89.589706 | L12: =SUM(K12)/SUM(C19:C20)*D19 -> 102.49592 | M12: =SUM(L12)/SUM(D19:D20)*E19 -> 117.25377 | N12: =SUM(M12)/SUM(E19:E20)*F19 -> 134.16421 | O12: =SUM(N12)/SUM(F19:F20)*G19 -> 153.64497 | Q12: Trade and other receivables | R12: 32.1 | S12: =+Assumptions!M16 -> 38.8 | T12: =AVERAGE(R12:S12) -> 35.45 | U12: =AVERAGE(S12:T12) -> 37.125 | V12: =AVERAGE(T12:U12) -> 36.2875 | W12: =AVERAGE(U12:V12) -> 36.70625
A13: Net credit losses on financial assets | B13: -12.5 | C13: =(-SUM(C$8:C$9)*0.2)*SUM($B13)/SUM($B$11:$B$13) -> -10.146081 | D13: =(-SUM(D$8:D$9)*0.25)*SUM($B13)/SUM($B$11:$B$13) -> -15.675979 | E13: =(-SUM(E$8:E$9)*0.3)*SUM($B13)/SUM($B$11:$B$13) -> -23.378501 | F13: =(-SUM(F$8:F$9)*0.35)*SUM($B13)/SUM($B$11:$B$13) -> -34.088655 | G13: =(-SUM(G$8:G$9)*0.4)*SUM($B13)/SUM($B$11:$B$13) -> -48.971309 | I13: Foreign Currecy Exchange difference | J13: 21.5 | K13: =-Assumptions!C36 -> 0.3 | L13: =-Assumptions!D36 -> 0.3 | M13: =-Assumptions!E36 -> 0.3 | N13: =-Assumptions!F36 -> 0.3 | O13: =-Assumptions!G36 -> 0.3 | Q13: Total non-current Assets | R13: =SUM(R9:R12) -> 175.9 | S13: =SUM(S9:S12) -> 179.16465 | T13: =SUM(T9:T12) -> 178.40611 | U13: =SUM(U9:U12) -> 177.41515 | V13: =SUM(V9:V12) -> 175.20516 | W13: =SUM(W9:W12) -> 173.42134
A14: Gross Profit | B14: =SUM(B8:B13) -> 1092.4 | C14: =SUM(C8:C13) -> 1444.1525 | D14: =SUM(D8:D13) -> 1673.4421 | E14: =SUM(E8:E13) -> 1941.1014 | F14: =SUM(F8:F13) -> 2252.7341 | G14: =SUM(G8:G13) -> 2613.8926 | I14: Current tax expenses | J14: 126.8 | K14: =-C28 -> 152.97262 | L14: =-D28 -> 186.26498 | M14: =-E28 -> 216.63302 | N14: =-F28 -> 247.07109 | O14: =-G28 -> 281.06613
I15: Interest received | J15: 344.4 | K15: =+S31*2% -> 379.39378 | L15: =+T31*2% -> 518.78739 | M15: =+U31*2% -> 709.39582 | N15: =+V31*2% -> 970.03597 | O15: =+W31*2% -> 1326.4383 | Q15: Current Assets
I16: Interest Paid | J16: -16.7 | K16: -10 | L16: -10 | M16: -10 | N16: -10 | O16: -10 | Q16: Current Tax assets | R16: 4 | S16: =+R16 -> 4 | T16: =+S16 -> 4 | U16: =+T16 -> 4 | V16: =+U16 -> 4 | W16: =+V16 -> 4
I17: Corporate Income tax paid | J17: -73.7 | K17: =SUM(J17)/SUM(J14)*K14 -> -88.912322 | L17: =SUM(K17)/SUM(K14)*L14 -> -108.26285 | M17: =SUM(L17)/SUM(L14)*M14 -> -125.91367 | N17: =SUM(M17)/SUM(M14)*N14 -> -143.6052 | O17: =SUM(N17)/SUM(N14)*O14 -> -163.36415 | Q17: Trade and other receivables | R17: 442.8 | S17: =+R17*1.5 -> 664.2 | T17: =+S17*1.5 -> 996.3 | U17: =+T17*1.5 -> 1494.45 | V17: =+U17*1.5 -> 2241.675 | W17: =+V17*1.5 -> 3362.5125
I18: Interest income and expenses | J18: -484.6 | K18: =-595+100 -> -495 | L18: -624.90531 | M18: =-1459.89329278549+750 -> -709.89329 | N18: =-2568.74146696922+1900 -> -668.74147 | O18: =-4060.73653671049+2800 -> -1260.7365 | Q18: Short-term financial investments | R18: 4033.9 | S18: =+R18*(1.11) -> 4477.629 | T18: =+S18*(1.11) -> 4970.1682 | U18: =+T18*(1.11) -> 5516.8867 | V18: =+U18*(1.11) -> 6123.7442 | W18: =+V18*(1.11) -> 6797.3561
A19: Administrative Expenses | B19: =-615.9+18.3 -> -597.6 | C19: =SUM(B19/B8)*C8-58.9 -> -761.08 | D19: =SUM(C19/C8)*D8 -> -894.67383 | E19: =SUM(D19/D8)*E8 -> -1052.1931 | F19: =SUM(E19/E8)*F8 -> -1238.0039 | G19: =SUM(F19/F8)*G8 -> -1457.2827 | I19: Fair value loss on financial assets as FVOCI | J19: 0.3 | Q19: Derivative financial assets | R19: 1.6 | S19: =+R19 -> 1.6 | T19: =+S19 -> 1.6 | U19: =+T19 -> 1.6 | V19: =+U19 -> 1.6 | W19: =+V19 -> 1.6
A20: Depreciation and amortisation | B20: -18.3 | C20: =-Assumptions!C45-Assumptions!C60 -> -20.937129 | D20: =-Assumptions!D45-Assumptions!D60 -> -25.087621 | E20: =-Assumptions!E45-Assumptions!E60 -> -29.769281 | F20: =-Assumptions!F45-Assumptions!F60 -> -34.508813 | G20: =-Assumptions!G45-Assumptions!G60 -> -39.599916 | I20: Effect of other non-monetary transactions | J20: 2.1 | Q20: Cash and cash equivalents | R20: 10479.2 | S20: =+K49 -> 15372.734 | T20: =+L49 -> 22077.463 | U20: =+M49 -> 31141.619 | V20: =+N49 -> 43499.785 | W20: =+O49 -> 60318.652
A21: Net interest income from corporate investments | B21: 19.7 | C21: =+B21 -> 19.7 | D21: =+C21 -> 19.7 | E21: =+D21 -> 19.7 | F21: =+E21 -> 19.7 | G21: =+F21 -> 19.7 | I21: Changes in operating assets and liabilities | Q21: Total Current Assets | R21: =SUM(R16:R20) -> 14961.5 | S21: =SUM(S16:S20) -> 20520.163 | T21: =SUM(T16:T20) -> 28049.531 | U21: =SUM(U16:U20) -> 38158.555 | V21: =SUM(V16:V20) -> 51870.804 | W21: =SUM(W16:W20) -> 70484.121
A22: Other operating income, net | B22: 5.7 | C22: =+B22 -> 5.7 | D22: =+C22 -> 5.7 | E22: =+D22 -> 5.7 | F22: =+E22 -> 5.7 | G22: =+F22 -> 5.7 | I22: Increase in prepayments and receivables | J22: -119.2 | K22: =SUM(J22/R17)*S17+SUM(R12-S12) -> -185.5 | L22: =SUM(K22/S17)*T17+SUM(S12-T12) -> -274.9 | M22: =SUM(L22/T17)*U17+SUM(T12-U12) -> -414.025 | N22: =SUM(M22/U17)*V17+SUM(U12-V12) -> -620.2 | O22: =SUM(N22/V17)*W17+SUM(V12-W12) -> -930.71875 | Q22: Total Assets | R22: =+R21+R13 -> 15137.4 | S22: =+S21+S13 -> 20699.328 | T22: =+T21+T13 -> 28227.937 | U22: =+U21+U13 -> 38335.97 | V22: =+V21+V13 -> 52046.009 | W22: =+W21+W13 -> 70657.542
A23: Operating Profit | B23: =SUM(B19:B22)+B14 -> 501.9 | C23: =SUM(C19:C22)+C14 -> 687.5354 | D23: =SUM(D19:D22)+D14 -> 779.08062 | E23: =SUM(E19:E22)+E14 -> 884.53901 | F23: =SUM(F19:F22)+F14 -> 1005.6214 | G23: =SUM(G19:G22)+G14 -> 1142.41 | I23: Increase in trade and other payables | J23: 58 | K23: =SUM(S31-R31)*0.03 -> 152.90966 | L23: =SUM(T31-S31)*0.03 -> 209.09043 | M23: =SUM(U31-T31)*0.03 -> 285.91264 | N23: =SUM(V31-U31)*0.03 -> 390.96022 | O23: =SUM(W31-V31)*0.03 -> 534.60349 | Q23: Non-current Liabilities
I24: Increase in receivables from customers and payment processors | J24: -72.7 | K24: =-S17+R17-K22 -> -35.9 | L24: =-T17+S17-L22 -> -57.2 | M24: =-U17+T17-M22 -> -84.125 | N24: =-V17+U17-N22 -> -127.025 | O24: =-W17+V17-O22 -> -190.11875 | Q24: Trade and other payables | R24: 46.1 | S24: 45.8 | T24: =AVERAGE(R24:S24) -> 45.95 | U24: =AVERAGE(S24:T24) -> 45.875 | V24: =AVERAGE(T24:U24) -> 45.9125 | W24: =AVERAGE(U24:V24) -> 45.89375
A25: Finance Expense | B25: -20.5 | C25: =-Assumptions!C98-10 -> -14.911874 | D25: =-Assumptions!D98-10 -> -19.092403 | E25: =-Assumptions!E98-10 -> -18.006915 | F25: =-Assumptions!F98-10 -> -17.337064 | G25: =-Assumptions!G98-10 -> -18.14546 | I25: Increase in liabilites to customers, payement processors and deferred revenue | J25: 228.6 | K25: =SUM(S31-R31)*0.07 -> 356.78922 | L25: =SUM(T31-S31)*0.07 -> 487.87766 | M25: =SUM(U31-T31)*0.07 -> 667.1295 | N25: =SUM(V31-U31)*0.07 -> 912.24052 | O25: =SUM(W31-V31)*0.07 -> 1247.4081 | Q25: Provisions | R25: 2.3 | S25: =+R25 -> 2.3 | T25: =+S25 -> 2.3 | U25: =+T25 -> 2.3 | V25: =+U25 -> 2.3 | W25: =+V25 -> 2.3
A26: Profit before tax | B26: =+B23+B25 -> 481.4 | C26: =+C23+C25 -> 672.62353 | D26: =+D23+D25 -> 759.98821 | E26: =+E23+E25 -> 866.53209 | F26: =+F23+F25 -> 988.28437 | G26: =+G23+G25 -> 1124.2645 | I26: Increase in wise accounts | J26: 2788.7 | K26: =SUM(S31-R31)*0.9 -> 4587.2899 | L26: =SUM(T31-S31)*0.9 -> 6272.7128 | M26: =SUM(U31-T31)*0.9 -> 8577.3793 | N26: =SUM(V31-U31)*0.9 -> 11728.807 | O26: =SUM(W31-V31)*0.9 -> 16038.105 | Q26: Deferred tax liabilites | R26: 2.4 | S26: =+R26 -> 2.4 | T26: =+S26 -> 2.4 | U26: =+T26 -> 2.4 | V26: =+U26 -> 2.4 | W26: =+V26 -> 2.4
I27: Net Cash generated from operating activities | J27: =SUM(J8:J26) -> 3248.9 | K27: =SUM(K8:K26) -> 5444.5206 | L27: =SUM(L8:L26) -> 7301.0719 | M27: =SUM(M8:M26) -> 9909.7155 | N27: =SUM(N8:N26) -> 13589.729 | O27: =SUM(O8:O26) -> 17909.426 | Q27: Borrowings | R27: 14.8 | S27: =+Assumptions!C73-Assumptions!C98 -> 81.288126 | T27: =+Assumptions!D73 -> 40.733333 | U27: =+Assumptions!E73 -> 49.477778 | V27: =+Assumptions!F73 -> 58.803704 | W27: =+Assumptions!G73 -> 49.671605
A28: Income tax expense | B28: -126.8 | C28: =SUM(B28/SUM(B8:B11))*SUM(C8:C11) -> -152.97262 | D28: =SUM(C28/SUM(C8:C11))*SUM(D8:D11) -> -186.26498 | E28: =-E26*0.25 -> -216.63302 | F28: =-F26*0.25 -> -247.07109 | G28: =-G26*0.25 -> -281.06613 | Q28: Total non-current Liabilities | R28: =SUM(R24:R27) -> 65.6 | S28: =SUM(S24:S27) -> 131.78813 | T28: =SUM(T24:T27) -> 91.383333 | U28: =SUM(U24:U27) -> 100.05278 | V28: =SUM(V24:V27) -> 109.4162 | W28: =SUM(W24:W27) -> 100.26535
I29: Cash Flows From Investing Activities:
A30: Profit for the year | B30: =+B26+B28 -> 354.6 | C30: =+C26+C28 -> 519.6509 | D30: =+D26+D28 -> 573.72323 | E30: =+E26+E28 -> 649.89907 | F30: =+F26+F28 -> 741.21328 | G30: =+G26+G28 -> 843.19839 | I30: Payments for property, plant and equipments | J30: -10.6 | K30: =-Assumptions!C34 -> -10.097872 | L30: =-Assumptions!D34 -> -17.898936 | M30: =-Assumptions!E34 -> -13.998404 | N30: =-Assumptions!F34 -> -15.94867 | O30: =-Assumptions!G34 -> -14.973537 | Q30: Current Liabilities
I31: Payments for intangibles assets | J31: -2.4 | K31: =-Assumptions!C60 -> -8.7806711 | L31: =-Assumptions!D60 -> -10.762405 | M31: =-Assumptions!E60 -> -12.947386 | N31: =-Assumptions!F60 -> -15.354199 | O31: =-Assumptions!G60 -> -18.030602 | Q31: Trade and other payables | R31: 13872.7 | S31: =+R31*(Assumptions!$M$25+1) -> 18969.689 | T31: =+S31*(Assumptions!$M$25+1) -> 25939.37 | U31: =+T31*(Assumptions!$M$25+1) -> 35469.791 | V31: =+U31*(Assumptions!$M$25+1) -> 48501.799 | W31: =+V31*(Assumptions!$M$25+1) -> 66321.915
A32: Other Comprehensive Income | I32: Payments for financial assets at FVOCI / Proceeds from sale & maturity of FA at FVOCI | J32: =-9552.3+9422.6 -> -129.7 | K32: =+R18-S18 -> -443.729 | L32: =+S18-T18 -> -492.53919 | M32: =+T18-U18 -> -546.7185 | N32: =+U18-V18 -> -606.85754 | O32: =+V18-W18 -> -673.61186 | Q32: Derivative financial liabilities | R32: 1.6 | S32: =+R32 -> 1.6 | T32: =+S32 -> 1.6 | U32: =+T32 -> 1.6 | V32: =+U32 -> 1.6 | W32: =+V32 -> 1.6
A33: Items that may be reclassified to profit or loss: | J33: 0 | Q33: Provisions | R33: 2.2 | S33: =+R33 -> 2.2 | T33: =+S33 -> 2.2 | U33: =+T33 -> 2.2 | V33: =+U33 -> 2.2 | W33: =+V33 -> 2.2
A34: Fair value gain/(loss) on investments, net | B34: 10.9 | C34: =+B34 -> 10.9 | D34: =+C34 -> 10.9 | E34: =+D34 -> 10.9 | F34: =+E34 -> 10.9 | G34: =+F34 -> 10.9 | I34: Proceeds from sublease | J34: 0.1 | Q34: Current tax liabilities | R34: 6 | S34: =+R34 -> 6 | T34: =+S34 -> 6 | U34: =+T34 -> 6 | V34: =+U34 -> 6 | W34: =+V34 -> 6
A35: Currency translation differences | B35: -7 | C35: =+B35 -> -7 | D35: =+C35 -> -7 | E35: =+D35 -> -7 | F35: =+E35 -> -7 | G35: =+F35 -> -7 | I35: Net Cash generated from Investing activities | J35: =SUM(J30:J34) -> -142.6 | K35: =SUM(K30:K34) -> -462.60754 | L35: =SUM(L30:L34) -> -521.20053 | M35: =SUM(M30:M34) -> -573.66429 | N35: =SUM(N30:N34) -> -638.16041 | O35: =SUM(O30:O34) -> -706.616 | Q35: Borrowings | R35: 209.4 | S35: =+Assumptions!C69 -> 99.4 | T35: =+Assumptions!D69 -> 184 | U35: =+Assumptions!E69 -> 162.03333 | V35: =+Assumptions!F69 -> 148.47778 | W35: =+Assumptions!G69 -> 164.83704
A36: Total other comprehensive income/(loss) | B36: =+B34+B35 -> 3.9 | C36: =+C34+C35 -> 3.9 | D36: =+D34+D35 -> 3.9 | E36: =+E34+E35 -> 3.9 | F36: =+F34+F35 -> 3.9 | G36: =+G34+G35 -> 3.9 | Q36: Total Non-Current Liabilities | R36: =SUM(R31:R35) -> 14091.9 | S36: =SUM(S31:S35) -> 19078.889 | T36: =SUM(T31:T35) -> 26133.17 | U36: =SUM(U31:U35) -> 35641.625 | V36: =SUM(V31:V35) -> 48660.076 | W36: =SUM(W31:W35) -> 66496.552
I37: Cash Flows From Financing Activities: | Q37: Total Liabilities | R37: =+R36+R28 -> 14157.5 | S37: =+S36+S28 -> 19210.677 | T37: =+T36+T28 -> 26224.553 | U37: =+U36+U28 -> 35741.677 | V37: =+V36+V28 -> 48769.493 | W37: =+W36+W28 -> 66596.817
I38: Funding relating to share purchase and employee share schemes | J38: -68.4 | K38: =-8.1-72 -> -80.1 | L38: =-72-8.1 -> -80.1 | M38: =-72-8.1 -> -80.1 | N38: =-72-8.1 -> -80.1 | O38: =-72-8.1 -> -80.1
I39: Proceeds from issue of shares and other equity | J39: 1 | K39: =+J39 -> 1 | L39: =+K39 -> 1 | M39: =+L39 -> 1 | N39: =+M39 -> 1 | O39: =+N39 -> 1 | Q39: Equity
I40: Proceeds from borrowings / Repayments from borrowings | J40: =420-470 -> -50 | K40: =-R35+S35-R27+S27 -> -43.511874 | L40: =-S35+T35-S27+T27 -> 44.045207 | M40: =-T35+U35-T27+U27 -> -13.222222 | N40: =-U35+V35-U27+V27 -> -4.2296296 | O40: =-V35+W35-V27+W27 -> 7.2271605 | Q40: Share Capital | R40: 10.2 | S40: =+R40 -> 10.2 | T40: 10.2 | U40: 10.2 | V40: 10.2 | W40: 10.2
A41: Total Comprehensive Income for the year | B41: =+B30+B36 -> 358.5 | C41: =+C30+C36 -> 523.5509 | D41: =+D30+D36 -> 577.62323 | E41: =+E30+E36 -> 653.79907 | F41: =+F30+F36 -> 745.11328 | G41: =+G30+G36 -> 847.09839 | J41: 0 | Q41: Equity merger reserve | R41: -8 | S41: =+R41 -> -8 | T41: =+S41 -> -8 | U41: =+T41 -> -8 | V41: =+U41 -> -8 | W41: =+V41 -> -8
I42: Principal elements of lease payments | J42: -7.1 | K42: =-Assumptions!C108 -> -35.88844 | L42: =-Assumptions!D108 -> -16.958884 | M42: =-Assumptions!E108 -> -20.599539 | N42: =-Assumptions!F108 -> -24.482288 | O42: =-Assumptions!G108 -> -20.680237 | Q42: Share-based payment reserve | R42: 306.5 | S42: =+R42-66.5+58.9 -> 298.9 | T42: =+S42-66.5+71 -> 303.4 | U42: =+T42-66.5+71 -> 307.9 | V42: =+U42-66.5+71 -> 312.4 | W42: =+V42-66.5+71 -> 316.9
A43: Number of Shares Issued: | I43: Inerest paid on leases | J43: -1.1 | K43: =-1.1-Assumptions!C98 -> -6.011874 | L43: =-1.1-Assumptions!D98 -> -10.192403 | M43: =-1.1-Assumptions!E98 -> -9.1069147 | N43: =-1.1-Assumptions!F98 -> -8.4370638 | O43: =-1.1-Assumptions!G98 -> -9.2454604 | Q43: Own shares reserve | R43: -55.5 | S43: =+R43-71+59.7 -> -66.8 | T43: =+S43-71.59 -> -138.39 | U43: =+T43-71.59 -> -209.98 | V43: =+U43-71.59 -> -281.57 | W43: =+V43-71.59 -> -353.16
A44: Basic | B44: 1036.7 | C44: 1036.7 | D44: 1036.7 | E44: 1036.7 | F44: 1036.7 | G44: 1036.7 | I44: Net Cash generated from Financing activities | J44: =SUM(J38:J43) -> -125.6 | K44: =SUM(K38:K43) -> -164.51219 | L44: =SUM(L38:L43) -> -62.206079 | M44: =SUM(M38:M43) -> -122.02868 | N44: =SUM(N38:N43) -> -116.24898 | O44: =SUM(O38:O43) -> -101.79854 | Q44: Other reserves | R44: -12.4 | S44: =+R44+10.3 -> -2.1 | T44: =+S44 -> -2.1 | U44: =+T44 -> -2.1 | V44: =+U44 -> -2.1 | W44: =+V44 -> -2.1
...

Sheet Assumptions
A1: Wise
A2: Assumptions
A6: Descriptions | B6: 45292 | C6: 45658 | D6: =EDATE(C6,12) -> 46023 | E6: =EDATE(D6,12) -> 46388 | F6: =EDATE(E6,12) -> 46753 | G6: =EDATE(F6,12) -> 47119 | M6: =EDATE(N6,12) -> 45658 | N6: =EDATE(O6,12) -> 45292 | O6: =EDATE(P6,12) -> 44927 | P6: =EDATE(Q6,12) -> 44562 | Q6: 44197 | V6: Details | W6: =EDATE(X6,12) -> 45658 | X6: =EDATE(Y6,12) -> 45292 | Y6: =EDATE(Z6,12) -> 44927 | Z6: =EDATE(AA6,12) -> 44562 | AA6: 44197 | AM6: ASSUMPTIONS
A7: Income Statement | M7: 1212 | N7: 1052 | O7: 846.1 | P7: 559.9 | Q7: 421 | W7: =+M7/M$9 -> 0.73673333 | X7: =+N7/N$9 -> 0.68436118 | Y7: =+O7/O$9 -> 0.87416055 | Z7: =+P7/P$9 -> 0.99308265 | AA7: =+Q7/Q$9 -> 1
A8: Revenue Growth | B8: Best Case | C8: 0.15 | D8: =AVERAGE($V$28:$V$29) -> 0.175 | E8: =AVERAGE($V$28:$V$29) -> 0.175 | F8: =AVERAGE($V$28:$V$29) -> 0.175 | G8: =AVERAGE($V$28:$V$29) -> 0.175 | M8: 433.1 | N8: 485.2 | O8: 121.8 | P8: 3.9 | V8: Grwoth Rate | W8: =+M8/M$9 -> 0.26326667 | X8: =+N8/N$9 -> 0.31563882 | Y8: =+O8/O$9 -> 0.12583945 | Z8: =+P8/P$9 -> 0.0069173466 | AA8: =+Q8/Q$9 -> 0
A9: Cost of materials consumed | B9: Base Case | C9: 0.08 | D9: 0.08 | E9: 0.08 | F9: 0.08 | G9: 0.08 | M9: =+M7+M8 -> 1645.1 | N9: =+N7+N8 -> 1537.2 | O9: =+O7+O8 -> 967.9 | P9: =+P7+P8 -> 563.8 | Q9: =+Q7+Q8 -> 421
A10: Purchase | B10: Worst Case | C10: 0.02 | D10: 0.02 | E10: 0.02 | F10: 0.02 | G10: 0.02 | V10: Average | W10: =AVERAGE(W8:AA8) -> 0.14233246
A11: Excise Duty | K11: Bank Fee | M11: =-328.1-9.1 -> -337.2 | N11: -307.4 | O11: -308.2 | P11: -185.8 | Q11: -151.7 | AL11: 1 | AM11: Revenue is assumed as an average of 15% and 20%, as per strategic report 2024. The average is the base case scenario and 15% is worst case and 20% is best case scenario.
A12: Changes in stock
A13: Employment Benefit Expenses | M13: =+M9+M11 -> 1307.9 | N13: =+N9+N11 -> 1229.8 | O13: =+O9+O11 -> 659.7 | P13: =+P9+P11 -> 378 | Q13: =+Q9+Q11 -> 269.3 | AL13: 2 | AM13: Interest income on customer balance is assumed to be 3% of wise account balance which forms the major part of trade and other payables.
A14: Employment Benefit Share based payment expense | M14: =+M13/M9 -> 0.79502766 | N14: =+N13/N9 -> 0.80002602 | O14: =+O13/O9 -> 0.68157868 | P14: =+P13/P9 -> 0.67045051 | Q14: =+Q13/Q9 -> 0.63966746
AL15: 3 | AM15: Depreciation and Amortisation costs are calculated based on the depreciation % on FA as per 2024 financial statements.
A16: Balance Sheet | K16: Non current trade and other receivables | M16: 38.8 | N16: 32.1 | O16: 17.9 | P16: 14.3 | Q16: 15.1
A17: Effective Interest Rate | B17: ='3 Statement Model'!#REF!/(+#REF!+#REF!)*-1 -> #REF! | C17: =AVERAGE(B17:B17) -> #REF! | D17: =AVERAGE(C17:C17) -> #REF! | E17: =AVERAGE(C17:D17) -> #REF! | F17: =AVERAGE(C17:E17) -> #REF! | G17: =AVERAGE(D17:F17) -> #REF! | AL17: 4 | AM17: Interest on RCF is SONIA plus margin which is ratio of debt to adjusted EBITDA, for calculating the margin, the adjusted EBITDA was calculated as
A18: Accounts Receivable Turnover | B18: =SUM('3 Statement Model'!B8:B11)/'3 Statement Model'!R12 -> 43.996885 | C18: =AVERAGE(B18:B18) -> 43.996885 | D18: =AVERAGE(C18:C18) -> 43.996885 | E18: =AVERAGE(C18:D18) -> 43.996885 | F18: =AVERAGE(C18:E18) -> 43.996885 | G18: =AVERAGE(D18:F18) -> 43.996885 | AM18: forecasted operating profit less net income from corporate investments less depreciation and amortisation less share based payment (12% of admin expense)
A19: Inventory Turnover | B19: =+'3 Statement Model'!B23/#REF!*-1 -> #REF! | C19: =AVERAGE(B19:B19) -> #REF! | D19: =AVERAGE(C19:C19) -> #REF! | E19: =AVERAGE(C19:D19) -> #REF! | F19: =AVERAGE(C19:E19) -> #REF! | G19: =AVERAGE(D19:F19) -> #REF! | K19: Customer Balance | M19: 17100 | N19: 13300 | O19: 10700 | P19: 6800 | AM19: The RCF and lease liabilities are calculated as the rolling average of last three years. The SONIA rate was taken from Bank of England 2022 to 2024 average which came to 3.69%
A20: Accounts Payable Turnover | B20: =+'3 Statement Model'!B23/#REF!*-1 -> #REF! | C20: =AVERAGE(B20:B20) -> #REF! | D20: =AVERAGE(C20:C20) -> #REF! | E20: =AVERAGE(C20:D20) -> #REF! | F20: =AVERAGE(C20:E20) -> #REF! | G20: =AVERAGE(D20:F20) -> #REF! | K20: Receivable from customer | M20: 97.1 | N20: 131.6 | O20: 23.9 | P20: 16.6 | AM20: and the leverage of 0.39, therefore, the pricing level fell under tier 1 and hence the margin was taken as 1.25%. Based on this the interest rate for this model is 4.69%.
A21: Depreciation as % of Gross Block | B21: =B45/B39 -> 0.16814159 | C21: =AVERAGE(B21:B21) -> 0.16814159 | D21: =AVERAGE(C21:C21) -> 0.16814159 | E21: =AVERAGE(C21:D21) -> 0.16814159 | F21: =AVERAGE(C21:E21) -> 0.16814159 | G21: =AVERAGE(D21:F21) -> 0.16814159 | M21: =+M20/M19 -> 0.0056783626 | N21: =+N20/N19 -> 0.0098947368 | O21: =+O20/O19 -> 0.0022336449 | P21: =+P20/P19 -> 0.0024411765 | AM21: This rate is also taken as cost of debt in calculating WACC.
A22: Ammortisation as a % of Gross Block | B22: =+B60/B55 -> 0.44230769 | C22: =AVERAGE(B22:B22) -> 0.44230769 | D22: =AVERAGE(C22:C22) -> 0.44230769 | E22: =AVERAGE(C22:D22) -> 0.44230769 | F22: =AVERAGE(C22:E22) -> 0.44230769 | G22: =AVERAGE(D22:F22) -> 0.44230769 | M22: =-SUM(N20-M20)/N20 -> -0.26215805 | N22: =-SUM(O20-N20)/O20 -> 4.5062762 | O22: =-SUM(P20-O20)/P20 -> 0.43975904
A23: Revenue / Gross Block (Tangible) | B23: =SUM('3 Statement Model'!B$8)/Assumptions!B33 -> 24.351852 | C23: =SUM('3 Statement Model'!C$8)/Assumptions!C33 -> 18.231563 | D23: =SUM('3 Statement Model'!D$8)/Assumptions!D33 -> 18.920772 | E23: =SUM('3 Statement Model'!E$8)/Assumptions!E33 -> 18.258189 | F23: =SUM('3 Statement Model'!F$8)/Assumptions!F33 -> 18.880575 | G23: =SUM('3 Statement Model'!G$8)/Assumptions!G33 -> 19.505146 | K23: 4 Year average of ratio of receivable from customer to customer balance | M23: =AVERAGE(M22:P22)/100 -> 0.015612924 | AL23: 5 | AM23: The cost of sales and other admin expenses are forecasted as a % of revenue and interest income taking 2024 as the base year.
A24: Revenue / Gross Block (Intangible) | B24: =+'3 Statement Model'!B8/Assumptions!B51 -> 77.352941 | C24: =SUM('3 Statement Model'!C$8)/Assumptions!C51 -> 79.237179 | D24: =SUM('3 Statement Model'!D$8)/Assumptions!D51 -> 60.283802 | E24: =SUM('3 Statement Model'!E$8)/Assumptions!E51 -> 48.848202 | F24: =SUM('3 Statement Model'!F$8)/Assumptions!F51 -> 40.876867 | G24: =SUM('3 Statement Model'!G$8)/Assumptions!G51 -> 35.076299 | K24: YOY % movement of customer balance | M24: =-SUM(N19-M19)/N19 -> 0.28571429 | N24: =-SUM(O19-N19)/O19 -> 0.24299065 | O24: =-SUM(P19-O19)/P19 -> 0.57352941
K25: 3 year average of customer balance | M25: =AVERAGE(M24:O24) -> 0.36741145 | AL25: 6 | AM25: 90% of accounts payable are assumed to be customer balance which is the movement of wise accounts in cashflow statement too.
A26: Debt/Equity | B26: =+#REF!/#REF! -> #REF! | C26: =AVERAGE(B26:B26) -> #REF! | D26: =AVERAGE(C26:C26) -> #REF! | E26: =AVERAGE(C26:D26) -> #REF! | F26: =AVERAGE(C26:E26) -> #REF! | G26: =AVERAGE(D26:F26) -> #REF!
A27: Other Liabilities turnover | B27: =+'3 Statement Model'!B23/#REF!*-1 -> #REF! | C27: =AVERAGE(B27:B27) -> #REF! | D27: =AVERAGE(C27:C27) -> #REF! | E27: =AVERAGE(C27:D27) -> #REF! | F27: =AVERAGE(C27:E27) -> #REF! | G27: =AVERAGE(D27:F27) -> #REF! | J27: =188*0.67 -> 125.96 | AL27: 7 | AM27: Cutomer balance is forecasted to grow at 37% each year. 37% is the average growth rate between FY2023 to FY2025.
A28: Dividend payout ratio | M28: 4654.9 | N28: 4039.9 | O28: 3804.5 | P28: 1192.4 | V28: 0.15 | W28: CAGR | X28: As per strategic report 2024
J29: =198*0.67 -> 132.66 | P29: =+P28/P27 -> #DIV/0! | V29: 0.2 | W29: CAGR | AL29: 8 | AM29: For estimating tangible and intangible assets, the month on month revenue change and adjust it by the size of the fixed asset base.
J30: =+J27-J29 -> -6.7 | M30: =SUM(N28-M28)/N28 -> -0.15223149 | N30: =SUM(O28-N28)/O28 -> -0.061874096 | O30: =SUM(P28-O28)/P28 -> -2.190624 | AM30: The size of fixed asset base is calculated by current month income divide by the opening fixed assets.
A31: ASSET SCHEDULE | C31: =+'3 Statement Model'!C8-'3 Statement Model'!B8 -> 184.1 | D31: =+C31/C23 -> 10.097872 | J31: =+J30/J27 -> -0.053191489
A32: Tangible Assets | V32: WORST | W32: BEST | X32: BASE | AL32: 9 | AM32: For calculating FCFE, the customer balance is removed from net cash generated from operations, as that is a liability and not true
A33: Gross Assets (Opening) | B33: =49.5-6.3 -> 43.2 | C33: =+B39 -> 67.8 | D33: =+C39 -> 76.797872 | E33: =+D39 -> 93.596809 | F33: =+E39 -> 106.49521 | G33: =+F39 -> 121.34388 | V33: =+'3 Statement Model'!$B$8*(1+Assumptions!V28) -> 1209.8 | W33: =+'3 Statement Model'!$B$8*(1+Assumptions!V29) -> 1262.4 | X33: =AVERAGE(V33:W33) -> 1236.1 | AM33: cash generated from operations which can be used for running the business.
A34: Acquisitions | B34: 25.7 | C34: =('3 Statement Model'!C8-'3 Statement Model'!B8)/C23 -> 10.097872 | D34: =AVERAGE(B34:C34) -> 17.898936 | E34: =AVERAGE(C34:D34) -> 13.998404 | F34: =AVERAGE(D34:E34) -> 15.94867 | G34: =AVERAGE(E34:F34) -> 14.973537 | V34: =+V33*(1+$V$28) -> 1391.27 | W34: =+W33*(1+$V$29) -> 1514.88 | X34: =AVERAGE(V34:W34) -> 1453.075
A35: Transitions | C35: 0 | D35: 0 | E35: 0 | F35: 0 | G35: 0 | M35: 347.6 | N35: 442.8 | O35: 250 | P35: 58 | Q35: 16 | V35: =+V34*(1+$V$28) -> 1599.9605 | W35: =+W34*(1+$V$29) -> 1817.856 | X35: =AVERAGE(V35:W35) -> 1708.9082
A36: Exchange Difference | B36: -0.3 | C36: =+B36 -> -0.3 | D36: =+C36 -> -0.3 | E36: =+D36 -> -0.3 | F36: =+E36 -> -0.3 | G36: =+F36 -> -0.3 | M36: =SUM(N35-M35)/N35 -> 0.21499548 | N36: =SUM(O35-N35)/O35 -> -0.7712 | O36: =SUM(P35-O35)/P35 -> -3.3103448 | P36: =SUM(Q35-P35)/Q35 -> -2.625 | V36: =+V35*(1+$V$28) -> 1839.9546 | W36: =+W35*(1+$V$29) -> 2181.4272 | X36: =AVERAGE(V36:W36) -> 2010.6909
A37: Adjustments | B37: -0.8 | C37: =+B37 -> -0.8 | D37: =+C37 -> -0.8 | E37: =+D37 -> -0.8 | F37: =+E37 -> -0.8 | G37: =+F37 -> -0.8 | V37: =+V36*(1+$V$28) -> 2115.9478 | W37: =+W36*(1+$V$29) -> 2617.7126 | X37: =AVERAGE(V37:W37) -> 2366.8302
A38: Disposal | B38: 0 | C38: 0 | D38: 0 | E38: 0 | F38: 0 | G38: 0 | V38: Period | W38: =+'3 Statement Model'!C6 -> 45658 | X38: =+'3 Statement Model'!D6 -> 46023 | Y38: =+'3 Statement Model'!E6 -> 46388 | Z38: =+'3 Statement Model'!F6 -> 46753 | AA38: =+'3 Statement Model'!G6 -> 47119
A39: Gross Assets (Ending) | B39: =SUM(B33:B37)-B38 -> 67.8 | C39: =SUM(C33:C37)-C38 -> 76.797872 | D39: =SUM(D33:D37)-D38 -> 93.596809 | E39: =SUM(E33:E37)-E38 -> 106.49521 | F39: =SUM(F33:F37)-F38 -> 121.34388 | G39: =SUM(G33:G37)-G38 -> 135.21742 | V39: Revenue | W39: =+INDEX($X$33:$X$37,COLUMN(A1)) -> 1236.1 | X39: =+INDEX($X$33:$X$37,COLUMN(B1)) -> 1453.075 | Y39: =+INDEX($X$33:$X$37,COLUMN(C1)) -> 1708.9082 | Z39: =+INDEX($X$33:$X$37,COLUMN(D1)) -> 2010.6909 | AA39: =+INDEX($X$33:$X$37,COLUMN(E1)) -> 2366.8302
A40: Average Gross Block | B40: =AVERAGE(B33,B39) -> 55.5 | C40: =AVERAGE(C33,C39) -> 72.298936 | D40: =AVERAGE(D33,D39) -> 85.19734 | E40: =AVERAGE(E33,E39) -> 100.04601 | F40: =AVERAGE(F33,F39) -> 113.91955 | G40: =AVERAGE(G33,G39) -> 128.28065
A42: Depreciation
A43: Accumulated Depreciation (Opening) | B43: =28.4-6.3 -> 22.1 | C43: =+B47 -> 33.5 | D43: =C47 -> 45.656458 | E43: =D47 -> 59.981675 | F43: =E47 -> 76.80357 | G43: =F47 -> 95.958185
A44: Accumulated Depreciation On Acquisitions During The Year/exchange difference | B44: 0 | C44: 0 | D44: 0 | E44: 0 | F44: 0 | G44: 0
...
